Workbook

Sheet README
A1: AI Pacing Economics Model — Input Data (v2, company-level)
A3: Edit any colored cell, save in Excel, then click "Reload Excel file" in AI Pacing Dashboard.html.
A5: COLOR CODE
A6: Blue = input you can edit (historical anchors are start-of-year: 2026 = Jan 1 2026).
A7: Orange = projections (2027-29, SemiAnalysis-informed).
A8: Green = LIVE FORMULA fed from the Companies sheet — edit the company rows instead, and these update.
A9: Gray = blank on purpose; the dashboard extrapolates from the Parameters sheet. Type a number to override.
A10: On Parameters: VALUE is what the dashboard uses; the orange Bullish/Normal/Bearish columns (where present)
A11: are the scenario sets applied by the dashboard's preset dropdown.
A13: NEW: THE COMPANIES SHEET
A14: One row per company (or 'Rest of…' aggregate) with CURRENT (mid-Aug 2026) verified figures:
A15: market cap, total debt, cash, EV (=cap+debt−cash), 2026E capex, AI ARR, ARR growth, % of revenue
... A43: SCMP, Fortune), IMF WEO Apr-26, World Bank, FRED/Fed Z.1, Epoch AI, SemiAnalysis, your prior models.

Sheet Companies
A1: Companies — current (mid-Aug 2026) verified figures + AI attribution judgments. Feeds the roll-up below → Sector sheets.
A3: Company | B3: Ticker | C3: Sector | D3: Block | E3: Mkt cap ($B) | F3: Total debt ($B) | G3: Cash ($B) | H3: EV ($B) | I3: CapEx 2026E ($B) | J3: AI ARR ($B) | K3: ARR growth (YoY) | L3: AI % of revenue | M3: AI % of EV | N3: % of EV from >2026 AI | O3: Cross-holdings ($B) | P3: AI-attrib mkt cap ($B) | Q3: AI-attrib debt ($B) | R3: Notes & sources
A4: NVIDIA | B4: NVDA | C4: PhysicalCompute | D4: USA | E4: 5450 | F4: 12.8 | G4: 53.2 | H4: =E4+F4-G4 -> 5409.6 | I4: 10 | J4: 300 | K4: 0.92 | L4: 0.92 | M4: 0.9 | N4: 0.6 | O4: 80 | P4: =E4*M4-O4 -> 4825 | Q4: =F4*M4 -> 11.52 | R4: Cap/debt/cash SA Aug-15-26. DC run-rate ~$300B/yr (Q1FY27 $75.2B, +92% YoY, 92% of rev). Cross-holdings: stakes in OpenAI/xAI/SSI/neoclouds ~$80B.
A5: Broadcom | B5: AVGO | C5: PhysicalCompute | D5: USA | E5: 1870 | F5: 64.9 | G5: 19.6 | H5: =E5+F5-G5 -> 1915.3 | I5: 3 | J5: 64 | K5: 1.8 | L5: 0.55 | M5: 0.6 | N5: 0.4 | O5: 0 | P5: =E5*M5-O5 -> 1122 | Q5: =F5*M5 -> 38.94 | R5: SA Aug-15 (fell 5.9% Aug-14). AI semi FY26 guide $56B (+180% YoY) ≈ half of revenue; VMware/legacy dilute.
A6: AMD | B6: AMD | C6: PhysicalCompute | D6: USA | E6: 840 | F6: 4.3 | G6: 13.1 | H6: =E6+F6-G6 -> 831.2 | I6: 2 | J6: 26 | K6: 0.57 | L6: 0.56 | M6: 0.55 | N6: 0.4 | O6: 0 | P6: =E6*M6-O6 -> 462 | Q6: =F6*M6 -> 2.365 | R6: SA Aug-15. MI400/OpenAI ramp; client/gaming still ~40% of rev.
A7: Marvell + rest of AI chip design | B7: MRVL+agg | C7: PhysicalCompute | D7: USA | E7: 250 | F7: 15 | G7: 10 | H7: =E7+F7-G7 -> 255 | I7: 2 | J7: 16 | K7: 0.5 | L7: 0.6 | M7: 0.6 | N7: 0.4 | O7: 0 | P7: =E7*M7-O7 -> 150 | Q7: =F7*M7 -> 9 | R7: Marvell ~$150B + Astera/Credo/etc. Custom AI silicon & interconnect. ESTIMATE agg.
A8: Arista Networks | B8: ANET | C8: PhysicalCompute | D8: USA | E8: 251 | F8: 0 | G8: 13.3 | H8: =E8+F8-G8 -> 237.7 | I8: 0.2 | J8: 7.4 | K8: 0.35 | L8: 0.7 | M8: 0.7 | N8: 0.45 | O8: 0 | P8: =E8*M8-O8 -> 175.7 | Q8: =F8*M8 -> 0 | R8: SA Aug-15. AI datacenter switching.
A9: Optics/interconnect agg (Coherent, Lumentum, Ciena, Celestica…) | B9: agg | C9: PhysicalCompute | D9: USA | E9: 350 | F9: 20 | G9: 15 | H9: =E9+F9-G9 -> 355 | I9: 4 | J9: 20 | K9: 0.6 | L9: 0.6 | M9: 0.6 | N9: 0.4 | O9: 0 | P9: =E9*M9-O9 -> 210 | Q9: =F9*M9 -> 12 | R9: AI optics boom. ESTIMATE agg.
A10: AI servers agg (Dell, HPE, SMCI slices) | B10: agg | C10: PhysicalCompute | D10: USA | E10: 350 | F10: 35 | G10: 20 | H10: =E10+F10-G10 -> 365 | I10: 4 | J10: 40 | K10: 0.5 | L10: 0.45 | M10: 0.45 | N10: 0.25 | O10: 0 | P10: =E10*M10-O10 -> 157.5 | Q10: =F10*M10 -> 15.75 | R10: Dell up ~4x on AI servers; PCs/storage dilute. ESTIMATE agg.
A11: Micron | B11: MU | C11: PhysicalCompute | D11: USA | E11: 1100 | F11: 6.4 | G11: 26 | H11: =E11+F11-G11 -> 1080.4 | I11: 33 | J11: 63 | K11: 2 | L11: 0.7 | M11: 0.7 | N11: 0.45 | O11: 0 | P11: =E11*M11-O11 -> 770 | Q11: =F11*M11 -> 4.48 | R11: SA Aug-15 ($1.10T; +682% y/y). HBM sold out through 2026; capex TTM $25.3B.
A12: Intel | B12: INTC | C12: PhysicalCompute | D12: USA | E12: 539 | F12: 50.5 | G12: 29.7 | H12: =E12+F12-G12 -> 559.8 | I12: 20 | J12: 12 | K12: 0.6 | L12: 0.18 | M12: 0.3 | N12: 0.2 | O12: 0 | P12: =E12*M12-O12 -> 161.7 | Q12: =F12*M12 -> 15.15 | R12: SA Aug-15 (+361% y/y on foundry/AI turnaround hopes); core is still PC/server CPUs.
A13: Applied Materials | B13: AMAT | C13: PhysicalCompute | D13: USA | E13: 403 | F13: 6.5 | G13: 9.2 | H13: =E13+F13-G13 -> 400.3 | I13: 2.8 | J13: 14 | K13: 0.35 | L13: 0.5 | M13: 0.45 | N13: 0.3 | O13: 0 | P13: =E13*M13-O13 -> 181.35 | Q13: =F13*M13 -> 2.925 | R13: SA Aug-15. Leading-edge demand AI-led but serves all chipmaking.
A14: Lam Research | B14: LRCX | C14: PhysicalCompute | D14: USA | E14: 416 | F14: 4.1 | G14: 5.6 | H14: =E14+F14-G14 -> 414.5 | I14: 1.2 | J14: 14 | K14: 0.5 | L14: 0.6 | M14: 0.45 | N14: 0.3 | O14: 0 | P14: =E14*M14-O14 -> 187.2 | Q14: =F14*M14 -> 1.845 | R14: SA Aug-15 ($416B — prior $270B/$490B both wrong).
A15: KLA | B15: KLAC | C15: PhysicalCompute | D15: USA | E15: 266 | F15: 6.2 | G15: 4.9 | H15: =E15+F15-G15 -> 267.3 | I15: 0.6 | J15: 7 | K15: 0.3 | L15: 0.5 | M15: 0.45 | N15: 0.3 | O15: 0 | P15: =E15*M15-O15 -> 119.7 | Q15: =F15*M15 -> 2.79 | R15: SA Aug-15 (10:1 split Jun-26).
... A18: Amazon | B18: AMZN | C18: PhysicalCompute | D18: USA | E18: 2830 | F18: 251.6 | G18: 123 | H18: =E18+F18-G18 -> 2958.6 | I18: 220 | J18: 169 | K18: 0.37 | L18: 0.25 | M18: 0.25 | N18: 0.15 | O18: 150 | P18: =E18*M18-O18 -> 557.5 | Q18: =F18*M18 -> 62.9 | R18: SA Aug-15. AWS run-rate ~$169B (+37%, accelerating); Trainium. Cross: Anthropic stake ≈ $150B netted.
A19: Meta | B19: META | C19: PhysicalCompute | D19: USA | E19: 1500 | F19: 112.3 | G19: 90.3 | H19: =E19+F19-G19 -> 1522 | I19: 130 | J19: 0 | L19: 0.15 | M19: 0.2 | N19: 0.12 | O19: 0 | P19: =E19*M19-O19 -> 300 | Q19: =F19*M19 -> 22.46 | R19: SA Aug-15. No external AI revenue; ads uplift + Llama/Muse; capex guide $115-139B.
A20: Oracle | B20: ORCL | C20: PhysicalCompute | D20: USA | E20: 434 | F20: 167.4 | G20: 31.9 | H20: =E20+F20-G20 -> 569.5 | I20: 75 | J20: 23 | K20: 0.93 | L20: 0.4 | M20: 0.55 | N20: 0.35 | O20: 0 | P20: =E20*M20-O20 -> 238.7 | Q20: =F20*M20 -> 92.07 | R20: SA Aug-15 (-38% over 52wk). OCI AI backlog; debt $167B, FCF deeply negative.
A21: CoreWeave | B21: CRWV | C21: PhysicalCompute | D21: USA | E21: 58.1 | F21: 51.6 | G21: 5.5 | H21: =E21+F21-G21 -> 104.2 | I21: 33 | J21: 19 | K21: 1.5 | L21: 1 | M21: 1 | N21: 0.6 | O21: 0 | P21: =E21*M21-O21 -> 58.1 | Q21: =F21*M21 -> 51.6 | R21: SA Aug-15. Debt $51.6B at Q2-26 (reported Aug-11; jumped from $35B) — EV ~$104B. 2026E rev ~$19B.
A22: Nebius | B22: NBIS | C22: PhysicalCompute | D22: USA | E22: 76.1 | F22: 10.2 | G22: 8 | H22: =E22+F22-G22 -> 78.3 | I22: 15 | J22: 6 | K22: 3 | L22: 1 | M22: 1 | N22: 0.6 | O22: 0 | P22: =E22*M22-O22 -> 76.1 | Q22: =F22*M22 -> 10.2 | R22: SA Aug-15. Neocloud; Microsoft offtake.
A23: Rest of neoclouds (Lambda, Crusoe, Together…) | B23: agg | C23: PhysicalCompute | D23: USA | E23: 90 | F23: 15 | G23: 8 | H23: =E23+F23-G23 -> 97 | I23: 15 | J23: 8 | K23: 1.5 | L23: 1 | M23: 1 | N23: 0.6 | O23: 0 | P23: =E23*M23-O23 -> 90 | Q23: =F23*M23 -> 15 | R23: Private neoclouds. ESTIMATE agg.
A24: Constellation Energy | B24: CEG | C24: PhysicalCompute | D24: USA | E24: 100 | F24: 24.7 | G24: 0.7 | H24: =E24+F24-G24 -> 124 | I24: 3.9 | J24: 0 | L24: 0.2 | M24: 0.25 | N24: 0.15 | O24: 0 | P24: =E24*M24-O24 -> 25 | Q24: =F24*M24 -> 6.175 | R24: SA Aug-15. Nuclear PPAs for AI DCs (MSFT/META).
A25: Vistra | B25: VST | C25: PhysicalCompute | D25: USA | E25: 49.7 | F25: 20.5 | G25: 0.4 | H25: =E25+F25-G25 -> 69.8 | I25: 2.9 | J25: 0 | L25: 0.15 | M25: 0.2 | N25: 0.12 | O25: 0 | P25: =E25*M25-O25 -> 9.94 | Q25: =F25*M25 -> 4.1 | R25: SA Aug-15.
A26: GE Vernova | B26: GEV | C26: PhysicalCompute | D26: USA | E26: 283 | F26: 3.7 | G26: 12.7 | H26: =E26+F26-G26 -> 274 | I26: 2.5 | J26: 0 | L26: 0.35 | M26: 0.3 | N26: 0.18 | O26: 0 | P26: =E26*M26-O26 -> 84.9 | Q26: =F26*M26 -> 1.11 | R26: SA Aug-15 ($283B — above both priors). Gas turbines/grid for DCs.
A27: Vertiv | B27: VRT | C27: PhysicalCompute | D27: USA | E27: 113 | F27: 3.3 | G27: 3.1 | H27: =E27+F27-G27 -> 113.2 | I27: 0.5 | J27: 9 | K27: 0.3 | L27: 0.8 | M27: 0.75 | N27: 0.45 | O27: 0 | P27: =E27*M27-O27 -> 84.75 | Q27: =F27*M27 -> 2.475 | R27: SA Aug-15. DC power/cooling.
A28: Rest of power/cooling/DC REITs (Eaton, Schneider, DLR, EQIX slices) | B28: agg | C28: PhysicalCompute | D28: USA | E28: 500 | F28: 120 | G28: 20 | H28: =E28+F28-G28 -> 600 | I28: 25 | J28: 25 | K28: 0.3 | L28: 0.25 | M28: 0.25 | N28: 0.15 | O28: 0 | P28: =E28*M28-O28 -> 125 | Q28: =F28*M28 -> 30 | R28: AI-relevant slices only. ESTIMATE agg.
A29: TSMC | B29: TSM | C29: PhysicalCompute | D29: ROW | E29: 2200 | F29: 33.6 | G29: 110.6 | H29: =E29+F29-G29 -> 2123 | I29: 52 | J29: 78 | K29: 1 | L29: 0.4 | M29: 0.55 | N29: 0.35 | O29: 0 | P29: =E29*M29-O29 -> 1210 | Q29: =F29*M29 -> 18.48 | R29: ADR-basis cap ~$2.2T (TWSE $1.94T) SA/CMC Aug-15. AI accelerators + HPC ≈ majority of growth; phones/auto dilute. Capex TTM $46.6B.
A30: SK Hynix | B30: 000660.KS | C30: PhysicalCompute | D30: ROW | E30: 827 | F30: 14 | G30: 68 | H30: =E30+F30-G30 -> 773 | I30: 30 | J30: 100 | K30: 1.8 | L30: 0.7 | M30: 0.75 | N30: 0.5 | O30: 0 | P30: =E30*M30-O30 -> 620.25 | Q30: =F30*M30 -> 10.5 | R30: CMC Aug-15 (corrected ~30% off Jul peak). HBM leader; US F-1 filed.
A31: Samsung Electronics | B31: 005930.KS | C31: PhysicalCompute | D31: ROW | E31: 1273 | F31: 17 | G31: 146 | H31: =E31+F31-G31 -> 1144 | I31: 45 | J31: 130 | K31: 2.5 | L31: 0.3 | M31: 0.3 | N31: 0.18 | O31: 0 | P31: =E31*M31-O31 -> 381.9 | Q31: =F31*M31 -> 5.1 | R31: CMC Aug-15. HBM re-rating; phones/appliances/display dilute.
A32: ASML | B32: ASML | C32: PhysicalCompute | D32: ROW | E32: 702 | F32: 2.3 | G32: 8.7 | H32: =E32+F32-G32 -> 695.6 | I32: 2 | J32: 20 | K32: 0.7 | L32: 0.5 | M32: 0.5 | N32: 0.32 | O32: 0 | P32: =E32*M32-O32 -> 351 | Q32: =F32*M32 -> 1.15 | R32: SA Aug-15. EUV demand AI-led but serves all leading-edge.
A33: Tokyo Electron | B33: 8035.T | C33: PhysicalCompute | D33: ROW | E33: 162 | F33: 0 | G33: 2.5 | H33: =E33+F33-G33 -> 159.5 | I33: 1.5 | J33: 9 | K33: 0.45 | L33: 0.55 | M33: 0.45 | N33: 0.3 | O33: 0 | P33: =E33*M33-O33 -> 72.9 | Q33: =F33*M33 -> 0 | R33: CMC Aug-15.
A34: Rest of SME (ASM Intl, Disco, Advantest…) | B34: agg | C34: PhysicalCompute | D34: ROW | E34: 250 | F34: 10 | G34: 15 | H34: =E34+F34-G34 -> 245 | I34: 3 | J34: 11 | K34: 0.5 | L34: 0.5 | M34: 0.45 | N34: 0.3 | O34: 0 | P34: =E34*M34-O34 -> 112.5 | Q34: =F34*M34 -> 4.5 | R34: ESTIMATE agg.
A35: Rest of foundry (GF, UMC, Rapidus…) | B35: agg | C35: PhysicalCompute | D35: ROW | E35: 145 | F35: 14.5 | G35: 22 | H35: =E35+F35-G35 -> 137.5 | I35: 10 | J35: 2 | K35: 0.3 | L35: 0.05 | M35: 0.1 | N35: 0.05 | O35: 0 | P35: =E35*M35-O35 -> 14.5 | Q35: =F35*M35 -> 1.45 | R35: Mostly trailing-edge. ESTIMATE agg.
A36: Cambricon | B36: 688256.SS | C36: PhysicalCompute | D36: CHN | E36: 148 | F36: 1 | G36: 3 | H36: =E36+F36-G36 -> 146 | I36: 1 | J36: 7 | K36: 2 | L36: 1 | M36: 1 | N36: 0.7 | O36: 0 | P36: =E36*M36-O36 -> 148 | Q36: =F36*M36 -> 1 | R36: ¥1T+ Jun-26, +77% YTD. Domestic AI accelerator champion.
A37: Hygon | B37: 688041.SS | C37: PhysicalCompute | D37: CHN | E37: 101 | F37: 1 | G37: 3 | H37: =E37+F37-G37 -> 99 | I37: 1 | J37: 8 | K37: 1 | L37: 0.85 | M37: 0.9 | N37: 0.6 | O37: 0 | P37: =E37*M37-O37 -> 90.9 | Q37: =F37*M37 -> 0.9 | R37: Domestic CPUs/DCUs; +67% YTD.
A38: SMIC | B38: 0981.HK | C38: PhysicalCompute | D38: CHN | E38: 73 | F38: 10 | G38: 15 | H38: =E38+F38-G38 -> 68 | I38: 7 | J38: 9 | K38: 0.5 | L38: 0.35 | M38: 0.4 | N38: 0.25 | O38: 0 | P38: =E38*M38-O38 -> 29.2 | Q38: =F38*M38 -> 4 | R38: N+2 7nm AI chips; mostly trailing-edge.
... A43: xAI | B43: private | C43: AICompanies | D43: USA | E43: 230 | F43: 5 | G43: 15 | H43: =E43+F43-G43 -> 220 | I43: 20 | J43: 2 | K43: 1.5 | L43: 0.85 | M43: 1 | N43: 0.88 | O43: 0 | P43: =E43*M43-O43 -> 230 | Q43: =F43*M43 -> 5 | R43: $230B Series E Jan-26 (NVIDIA-led); secondaries ~$250B.
A44: Safe Superintelligence | B44: private | C44: AICompanies | D44: USA | E44: 32 | F44: 0 | G44: 7 | H44: =E44+F44-G44 -> 25 | I44: 2 | J44: 0 | L44: 1 | M44: 1 | N44: 0.95 | O44: 0 | P44: =E44*M44-O44 -> 32 | Q44: =F44*M44 -> 0 | R44: $32B Apr-25; +$5B NVIDIA investment Jul-26. No product.
A45: Perplexity | B45: private | C45: AICompanies | D45: USA | E45: 20 | F45: 0 | G45: 1.5 | H45: =E45+F45-G45 -> 18.5 | I45: 0.2 | J45: 0.5 | K45: 3.35 | L45: 1 | M45: 1 | N45: 0.8 | O45: 0 | P45: =E45*M45-O45 -> 20 | Q45: =F45*M45 -> 0 | R45: ESTIMATE ~$20B.
A46: Rest of US AI-native (Cursor, Cognition, Harvey…) | B46: agg | C46: AICompanies | D46: USA | E46: 155 | F46: 0 | G46: 8 | H46: =E46+F46-G46 -> 147 | I46: 1 | J46: 8 | K46: 2.3 | L46: 1 | M46: 1 | N46: 0.8 | O46: 0 | P46: =E46*M46-O46 -> 155 | Q46: =F46*M46 -> 0 | R46: Coding/agent startups; Cursor et al +$6B ARR (SemiAnalysis). ESTIMATE agg.
A47: DeepSeek | B47: private | C47: AICompanies | D47: CHN | E47: 60 | F47: 0 | G47: 5 | H47: =E47+F47-G47 -> 55 | I47: 3 | J47: 1.5 | K47: 2 | L47: 1 | M47: 1 | N47: 0.85 | O47: 0 | P47: =E47*M47-O47 -> 60 | Q47: =F47*M47 -> 0 | R47: First round Jun-26 $7.4B at >$50B; seeking $71B pre-IPO.
...

Sheet GDP
A1: Y — Nominal GDP by country-block ($B).
A3: Key | B3: Series | C3: 2022 | D3: 2023 | E3: 2024 | F3: 2025 | G3: 2026 | H3: 2027 | I3: 2028 | J3: 2029 | K3: 2030 | L3: 2031 | M3: 2032 | N3: 2033 | O3: 2034 | P3: 2035 | Q3: Units | R3: Source / Assumption
A4: Y|USA | B4: GDP, USA ($B) | C4: 26055 | D4: 27812 | E4: 29298 | F4: 30767 | G4: 32384 | H4: 33790 | I4: 35066 | J4: 36361 | K4: 37678 | L4: 39031 | Q4: $B/yr | R4: IMF WEO Apr-2026 (Datamapper API NGDPD). 2025 = IMF estimate; 2027-31 = IMF projections.
A5: Y|CHN | B5: GDP, China ($B) | C5: 18338 | D5: 18367 | E5: 18945 | F5: 19626 | G5: 20852 | H5: 21929 | I5: 23260 | J5: 24663 | K5: 26047 | L5: 27497 | Q5: $B/yr | R5: IMF WEO Apr-2026, same source.
A6: Y|ROW | B6: GDP, Rest of World ($B) | C6: 58278 | D6: 61067 | E6: 63355 | F6: 67782 | G6: 73060 | H6: 76172 | I6: 79803 | J6: 83646 | K6: 87664 | L6: 91864 | Q6: $B/yr | R6: IMF WEO Apr-2026: World minus USA minus China (computed).

Sheet StockMarket
A1: W — Aggregate stock market capitalization ($B), value at START of year (Jan 1).
A3: Key | B3: Series | C3: 2022 | D3: 2023 | E3: 2024 | F3: 2025 | G3: 2026 | H3: 2027 | I3: 2028 | J3: 2029 | K3: 2030 | L3: 2031 | M3: 2032 | N3: 2033 | O3: 2034 | P3: 2035 | Q3: Units | R3: Source / Assumption
A4: W|USA | B4: Total US equity market cap ($B) | C4: 53000 | D4: 40510 | E4: 50780 | F4: 62200 | G4: 68940 | Q4: $B | R4: Siblis Research / World Bank WDI (end of prior year). 2022.0 ESTIMATE ~$53T. Mid-2026 ≈ $75T for reference.
A5: W|CHN | B5: China (mainland A-share) market cap ($B) | C5: 13200 | D5: 11470 | E5: 10940 | F5: 11760 | G5: 15510 | Q5: $B | R5: World Bank WDI. Excludes HK-listed Chinese cos (~+$5-6T if included). Mid-2026 A-shares ≈ $16.6-17T.
A6: W|ROW | B6: Rest of World market cap ($B) | C6: 45800 | D6: 41520 | E6: 41180 | F6: 41140 | G6: 56850 | Q6: $B | R6: World Bank WDI world total minus USA minus China. 2022.0 ESTIMATE.

Sheet Compute
A1: C — Installed AI compute stock (M H100-equivalents), START of year. γ = H100e rental rate.
A3: Key | B3: Series | C3: 2022 | D3: 2023 | E3: 2024 | F3: 2025 | G3: 2026 | H3: 2027 | I3: 2028 | J3: 2029 | K3: 2030 | L3: 2031 | M3: 2032 | N3: 2033 | O3: 2034 | P3: 2035 | Q3: Units | R3: Source / Assumption
A4: C|USA | B4: AI compute stock, USA (M H100e) | C4: 0.15 | D4: 0.41 | E4: 1.5 | F4: 4.9 | G4: 15 | H4: 33.8 | I4: 67.5 | J4: 124.8 | Q4: M H100e | R4: Epoch AI chip-sales (cumulative sold ≈20M world at Jan-26; operational 12-16M) × ~75% US share. 2027-29 = SemiAnalysis/Plan-A-informed Normal path.
A5: C|CHN | B5: AI compute stock, China (M H100e) | C5: 0.02 | D5: 0.06 | E5: 0.25 | F5: 0.85 | G5: 2.6 | H5: 5.4 | I5: 9.9 | J5: 16.6 | Q5: M H100e | R5: China ≈13% of world declining to ~10% by 2029 (Epoch, AI-2027 tracker, Plan A). ESTIMATE.
A6: C|ROW | B6: AI compute stock, RoW (M H100e) | C6: 0.03 | D6: 0.08 | E6: 0.25 | F6: 0.75 | G6: 2.4 | H6: 5.8 | I6: 12.6 | J6: 25 | Q6: M H100e | R6: Residual; share rises ~12→15% on Gulf/EU builds. ESTIMATE.
A7: gamma | B7: GPU rental rate γ ($/hr per H100e) | C7: 8 | D7: 5.5 | E7: 3.5 | F7: 2.2 | G7: 2 | H7: 1.8 | I7: 1.8 | J7: 1.8 | Q7: $/hr | R7: Blended neocloud/marketplace H100 rates (Silicon Data index; SemiAnalysis 'Great GPU Shortage'). $1.80 default 2027+ per your pause econ model.

Sheet Capabilities
A1: Z — AI capability level (Epoch Capabilities Index, ECI points), best model, START of year.
A3: Key | B3: Series | C3: 2022 | D3: 2023 | E3: 2024 | F3: 2025 | G3: 2026 | H3: 2027 | I3: 2028 | J3: 2029 | K3: 2030 | L3: 2031 | M3: 2032 | N3: 2033 | O3: 2034 | P3: 2035 | Q3: Units | R3: Source / Assumption
A4: Z|USA | B4: Best US model ECI | C4: 105 | D4: 117 | E4: 126 | F4: 142 | G4: 155 | Q4: ECI pts | R4: Epoch ECI: GPT-4 =125.8, o1 =142.3 (Dec-24), Gemini 3 Pro =154 (Dec-25) → 155 at 2026.0 (spec calibration). Mid-26: GPT-5.5 Pro =161. 2022.0 ESTIMATE.
A5: Z|CHN | B5: Best China model ECI | C5: 92 | D5: 102 | E5: 117 | F5: 136.5 | G5: 148 | Q5: ECI pts | R5: Epoch: Yi-34B =117.3 (end-23), DeepSeek-V3 =136.5 (Dec-24), Kimi K2 =145.1 (Nov-25) → 148 (spec). Mid-26: Kimi K3 =156. Lag ≈7 months avg.
A6: Z|ROW | B6: Best RoW model ECI | C6: 92 | D6: 102 | E6: 117 | F6: 136.5 | G6: 148 | Q6: ECI pts | R6: Model spec sets Z_RoW = Z_China.

Sheet Capex
A1: X — Worldwide AI investment/capex flow ($B during year) = X_BAU.
A3: Key | B3: Series | C3: 2022 | D3: 2023 | E3: 2024 | F3: 2025 | G3: 2026 | H3: 2027 | I3: 2028 | J3: 2029 | K3: 2030 | L3: 2031 | M3: 2032 | N3: 2033 | O3: 2034 | P3: 2035 | Q3: Units | R3: Source / Assumption
A4: X|WORLD | B4: AI capex, world ($B/yr) | C4: 129 | D4: 220 | E4: 374 | F4: 635 | G4: 1000 | H4: 1600 | I4: 2400 | J4: 3200 | Q4: $B/yr | R4: 2022-25 per your pause econ model; 2026 ~$1T (Dell'Oro/Epoch; top-5 guides ~$750B — see Companies capex column: raw 2026E capex of listed cos ≈ $1.1T all-purpose, AI share ~2/3). 2027-29 Normal +60/50/33%; SemiAnalysis cum 24-29 ≈$11.1T. Bullish preset ≈ your hotter path.

Sheet Sector_MarketCap
A1: M — AI-specific market cap by actor × block ($B), START of year. GREEN 2026 = live from Companies. NonAI = W − Σ(these).
A3: Key | B3: Series | C3: 2022 | D3: 2023 | E3: 2024 | F3: 2025 | G3: 2026 | H3: 2027 | I3: 2028 | J3: 2029 | K3: 2030 | L3: 2031 | M3: 2032 | N3: 2033 | O3: 2034 | P3: 2035 | Q3: Units | R3: Source / Assumption
A4: M|PhysicalCompute|USA | B4: PhysicalCompute, USA | C4: 600 | D4: 450 | E4: 2500 | F4: 6000 | G4: =Companies!F74 -> 9596.912 | Q4: $B | R4: 2022-25: ESTIMATE — same company set as Companies sheet, historical caps × time-varying AI fractions. 2026 (green) = LIVE from Companies roll-up: Σ(cap × %EV-AI − cross-holdings) ÷ (1 + H1-2026 return). Edit companies, not this cell.
A5: M|PhysicalCompute|CHN | B5: PhysicalCompute, China | C5: 15 | D5: 15 | E5: 60 | F5: 150 | G5: =Companies!F75 -> 300.70968 | Q5: $B | R5: 2022-25: ESTIMATE — same company set as Companies sheet, historical caps × time-varying AI fractions. 2026 (green) = LIVE from Companies roll-up: Σ(cap × %EV-AI − cross-holdings) ÷ (1 + H1-2026 return). Edit companies, not this cell.
A6: M|PhysicalCompute|ROW | B6: PhysicalCompute, RoW | C6: 250 | D6: 200 | E6: 400 | F6: 850 | G6: =Companies!F76 -> 1973.6071 | Q6: $B | R6: 2022-25: ESTIMATE — same company set as Companies sheet, historical caps × time-varying AI fractions. 2026 (green) = LIVE from Companies roll-up: Σ(cap × %EV-AI − cross-holdings) ÷ (1 + H1-2026 return). Edit companies, not this cell.
A7: M|NonPhysicalInputs|USA | B7: NonPhysicalInputs, USA | C7: 8 | D7: 10 | E7: 18 | F7: 35 | G7: =Companies!F77 -> 74.645833 | Q7: $B | R7: 2022-25: ESTIMATE — same company set as Companies sheet, historical caps × time-varying AI fractions. 2026 (green) = LIVE from Companies roll-up: Σ(cap × %EV-AI − cross-holdings) ÷ (1 + H1-2026 return). Edit companies, not this cell.
A8: M|NonPhysicalInputs|CHN | B8: NonPhysicalInputs, China | C8: 2 | D8: 2 | E8: 4 | F8: 8 | G8: =Companies!F78 -> 12.5 | Q8: $B | R8: 2022-25: ESTIMATE — same company set as Companies sheet, historical caps × time-varying AI fractions. 2026 (green) = LIVE from Companies roll-up: Σ(cap × %EV-AI − cross-holdings) ÷ (1 + H1-2026 return). Edit companies, not this cell.
A9: M|NonPhysicalInputs|ROW | B9: NonPhysicalInputs, RoW | C9: 1 | D9: 1 | E9: 2 | F9: 5 | G9: =Companies!F79 -> 8.3333333 | Q9: $B | R9: 2022-25: ESTIMATE — same company set as Companies sheet, historical caps × time-varying AI fractions. 2026 (green) = LIVE from Companies roll-up: Σ(cap × %EV-AI − cross-holdings) ÷ (1 + H1-2026 return). Edit companies, not this cell.
A10: M|AICompanies|USA | B10: AICompanies, USA | C10: 40 | D10: 60 | E10: 180 | F10: 320 | G10: =Companies!F80 -> 1285.1429 | Q10: $B | R10: 2022-25: ESTIMATE — same company set as Companies sheet, historical caps × time-varying AI fractions. 2026 (green) = LIVE from Companies roll-up: Σ(cap × %EV-AI − cross-holdings) ÷ (1 + H1-2026 return). Edit companies, not this cell.
A11: M|AICompanies|CHN | B11: AICompanies, China | C11: 2 | D11: 5 | E11: 15 | F11: 40 | G11: =Companies!F81 -> 103.2 | Q11: $B | R11: 2022-25: ESTIMATE — same company set as Companies sheet, historical caps × time-varying AI fractions. 2026 (green) = LIVE from Companies roll-up: Σ(cap × %EV-AI − cross-holdings) ÷ (1 + H1-2026 return). Edit companies, not this cell.
A12: M|AICompanies|ROW | B12: AICompanies, RoW | C12: 1 | D12: 3 | E12: 10 | F12: 25 | G12: =Companies!F82 -> 32.307692 | Q12: $B | R12: 2022-25: ESTIMATE — same company set as Companies sheet, historical caps × time-varying AI fractions. 2026 (green) = LIVE from Companies roll-up: Σ(cap × %EV-AI − cross-holdings) ÷ (1 + H1-2026 return). Edit companies, not this cell.
A13: M|AIDeployers|USA | B13: AIDeployers, USA | C13: 30 | D13: 40 | E13: 200 | F13: 420 | G13: =Companies!F83 -> 720.31818 | Q13: $B | R13: 2022-25: ESTIMATE — same company set as Companies sheet, historical caps × time-varying AI fractions. 2026 (green) = LIVE from Companies roll-up: Σ(cap × %EV-AI − cross-holdings) ÷ (1 + H1-2026 return). Edit companies, not this cell.
A14: M|AIDeployers|CHN | B14: AIDeployers, China | C14: 5 | D14: 8 | E14: 30 | F14: 80 | G14: =Companies!F84 -> 142 | Q14: $B | R14: 2022-25: ESTIMATE — same company set as Companies sheet, historical caps × time-varying AI fractions. 2026 (green) = LIVE from Companies roll-up: Σ(cap × %EV-AI − cross-holdings) ÷ (1 + H1-2026 return). Edit companies, not this cell.
A15: M|AIDeployers|ROW | B15: AIDeployers, RoW | C15: 5 | D15: 8 | E15: 30 | F15: 80 | G15: =Companies!F85 -> 108.33333 | Q15: $B | R15: 2022-25: ESTIMATE — same company set as Companies sheet, historical caps × time-varying AI fractions. 2026 (green) = LIVE from Companies roll-up: Σ(cap × %EV-AI − cross-holdings) ÷ (1 + H1-2026 return). Edit companies, not this cell.

Sheet Sector_Debt
A1: D — AI-attributable debt by actor × block ($B), START of year. GREEN 2026 = live from Companies.
A3: Key | B3: Series | C3: 2022 | D3: 2023 | E3: 2024 | F3: 2025 | G3: 2026 | H3: 2027 | I3: 2028 | J3: 2029 | K3: 2030 | L3: 2031 | M3: 2032 | N3: 2033 | O3: 2034 | P3: 2035 | Q3: Units | R3: Source / Assumption
A4: D|PhysicalCompute|USA | B4: PhysicalCompute, USA | C4: 7.2 | D4: 17 | E4: 52.9 | F4: 151 | G4: =Companies!G74 -> 377.57422 | Q4: $B | R4: 2022-25: ESTIMATE — scaled from the 2026 anchor (ratios 2/4.5/14/40%), consistent with BofA $121B hyperscaler bonds 2025, Morgan Stanley ~$570B AI issuance 2026, SemiAnalysis >$7T by 2029. 2026 (green) = LIVE from Companies roll-up: Σ(debt × %EV-AI) ÷ (1 + H1 debt growth).
A5: D|PhysicalCompute|CHN | B5: PhysicalCompute, China | C5: 0.5 | D5: 1.2 | E5: 3.8 | F5: 10.9 | G5: =Companies!G75 -> 27.265625 | Q5: $B | R5: 2022-25: ESTIMATE — scaled from the 2026 anchor (ratios 2/4.5/14/40%), consistent with BofA $121B hyperscaler bonds 2025, Morgan Stanley ~$570B AI issuance 2026, SemiAnalysis >$7T by 2029. 2026 (green) = LIVE from Companies roll-up: Σ(debt × %EV-AI) ÷ (1 + H1 debt growth).
A6: D|PhysicalCompute|ROW | B6: PhysicalCompute, RoW | C6: 0.6 | D6: 1.4 | E6: 4.5 | F6: 12.9 | G6: =Companies!G76 -> 32.171875 | Q6: $B | R6: 2022-25: ESTIMATE — scaled from the 2026 anchor (ratios 2/4.5/14/40%), consistent with BofA $121B hyperscaler bonds 2025, Morgan Stanley ~$570B AI issuance 2026, SemiAnalysis >$7T by 2029. 2026 (green) = LIVE from Companies roll-up: Σ(debt × %EV-AI) ÷ (1 + H1 debt growth).
A7: D|NonPhysicalInputs|USA | B7: NonPhysicalInputs, USA | C7: 0 | D7: 0 | E7: 0 | F7: 0 | G7: =Companies!G77 -> 0 | Q7: $B | R7: 2022-25: ESTIMATE — scaled from the 2026 anchor (ratios 2/4.5/14/40%), consistent with BofA $121B hyperscaler bonds 2025, Morgan Stanley ~$570B AI issuance 2026, SemiAnalysis >$7T by 2029. 2026 (green) = LIVE from Companies roll-up: Σ(debt × %EV-AI) ÷ (1 + H1 debt growth).
A8: D|NonPhysicalInputs|CHN | B8: NonPhysicalInputs, China | C8: 0 | D8: 0 | E8: 0 | F8: 0 | G8: =Companies!G78 -> 0 | Q8: $B | R8: 2022-25: ESTIMATE — scaled from the 2026 anchor (ratios 2/4.5/14/40%), consistent with BofA $121B hyperscaler bonds 2025, Morgan Stanley ~$570B AI issuance 2026, SemiAnalysis >$7T by 2029. 2026 (green) = LIVE from Companies roll-up: Σ(debt × %EV-AI) ÷ (1 + H1 debt growth).
A9: D|NonPhysicalInputs|ROW | B9: NonPhysicalInputs, RoW | C9: 0 | D9: 0 | E9: 0 | F9: 0 | G9: =Companies!G79 -> 0 | Q9: $B | R9: 2022-25: ESTIMATE — scaled from the 2026 anchor (ratios 2/4.5/14/40%), consistent with BofA $121B hyperscaler bonds 2025, Morgan Stanley ~$570B AI issuance 2026, SemiAnalysis >$7T by 2029. 2026 (green) = LIVE from Companies roll-up: Σ(debt × %EV-AI) ÷ (1 + H1 debt growth).
A10: D|AICompanies|USA | B10: AICompanies, USA | C10: 0.1 | D10: 0.2 | E10: 0.5 | F10: 1.6 | G10: =Companies!G80 -> 3.90625 | Q10: $B | R10: 2022-25: ESTIMATE — scaled from the 2026 anchor (ratios 2/4.5/14/40%), consistent with BofA $121B hyperscaler bonds 2025, Morgan Stanley ~$570B AI issuance 2026, SemiAnalysis >$7T by 2029. 2026 (green) = LIVE from Companies roll-up: Σ(debt × %EV-AI) ÷ (1 + H1 debt growth).
A11: D|AICompanies|CHN | B11: AICompanies, China | C11: 0 | D11: 0 | E11: 0 | F11: 0 | G11: =Companies!G81 -> 0 | Q11: $B | R11: 2022-25: ESTIMATE — scaled from the 2026 anchor (ratios 2/4.5/14/40%), consistent with BofA $121B hyperscaler bonds 2025, Morgan Stanley ~$570B AI issuance 2026, SemiAnalysis >$7T by 2029. 2026 (green) = LIVE from Companies roll-up: Σ(debt × %EV-AI) ÷ (1 + H1 debt growth).
A12: D|AICompanies|ROW | B12: AICompanies, RoW | C12: 0 | D12: 0 | E12: 0.1 | F12: 0.2 | G12: =Companies!G82 -> 0.625 | Q12: $B | R12: 2022-25: ESTIMATE — scaled from the 2026 anchor (ratios 2/4.5/14/40%), consistent with BofA $121B hyperscaler bonds 2025, Morgan Stanley ~$570B AI issuance 2026, SemiAnalysis >$7T by 2029. 2026 (green) = LIVE from Companies roll-up: Σ(debt × %EV-AI) ÷ (1 + H1 debt growth).
A13: D|AIDeployers|USA | B13: AIDeployers, USA | C13: 0.5 | D13: 1.1 | E13: 3.4 | F13: 9.6 | G13: =Companies!G83 -> 24.007812 | Q13: $B | R13: 2022-25: ESTIMATE — scaled from the 2026 anchor (ratios 2/4.5/14/40%), consistent with BofA $121B hyperscaler bonds 2025, Morgan Stanley ~$570B AI issuance 2026, SemiAnalysis >$7T by 2029. 2026 (green) = LIVE from Companies roll-up: Σ(debt × %EV-AI) ÷ (1 + H1 debt growth).
A14: D|AIDeployers|CHN | B14: AIDeployers, China | C14: 0.2 | D14: 0.6 | E14: 1.8 | F14: 5 | G14: =Companies!G84 -> 12.5 | Q14: $B | R14: 2022-25: ESTIMATE — scaled from the 2026 anchor (ratios 2/4.5/14/40%), consistent with BofA $121B hyperscaler bonds 2025, Morgan Stanley ~$570B AI issuance 2026, SemiAnalysis >$7T by 2029. 2026 (green) = LIVE from Companies roll-up: Σ(debt × %EV-AI) ÷ (1 + H1 debt growth).
A15: D|AIDeployers|ROW | B15: AIDeployers, RoW | C15: 0.2 | D15: 0.5 | E15: 1.4 | F15: 4.1 | G15: =Companies!G85 -> 10.15625 | Q15: $B | R15: 2022-25: ESTIMATE — scaled from the 2026 anchor (ratios 2/4.5/14/40%), consistent with BofA $121B hyperscaler bonds 2025, Morgan Stanley ~$570B AI issuance 2026, SemiAnalysis >$7T by 2029. 2026 (green) = LIVE from Companies roll-up: Σ(debt × %EV-AI) ÷ (1 + H1 debt growth).

Sheet Sector_Cash
A1: c — Cash on hand by actor × block ($B), START of year. Used only in E = M + D − c.
A3: Key | B3: Series | C3: 2022 | D3: 2023 | E3: 2024 | F3: 2025 | G3: 2026 | H3: 2027 | I3: 2028 | J3: 2029 | K3: 2030 | L3: 2031 | M3: 2032 | N3: 2033 | O3: 2034 | P3: 2035 | Q3: Units | R3: Source / Assumption
A4: c|PhysicalCompute|USA | B4: PhysicalCompute, USA | C4: 13.1 | D4: 20.9 | E4: 52.4 | F4: 130.9 | G4: 261.9 | Q4: $B | R4: AI-slice cash = Σ(cash × %EV-AI) from Companies × 0.8 scale-back for 2026.0; history scaled 5/8/20/50%. Used only in E = M + D − c. ESTIMATE.
A5: c|PhysicalCompute|CHN | B5: PhysicalCompute, China | C5: 1.3 | D5: 2 | E5: 5 | F5: 12.6 | G5: 25.2 | Q5: $B | R5: AI-slice cash = Σ(cash × %EV-AI) from Companies × 0.8 scale-back for 2026.0; history scaled 5/8/20/50%. Used only in E = M + D − c. ESTIMATE.
A6: c|PhysicalCompute|ROW | B6: PhysicalCompute, RoW | C6: 6.8 | D6: 10.9 | E6: 27.2 | F6: 68 | G6: 136 | Q6: $B | R6: AI-slice cash = Σ(cash × %EV-AI) from Companies × 0.8 scale-back for 2026.0; history scaled 5/8/20/50%. Used only in E = M + D − c. ESTIMATE.
A7: c|NonPhysicalInputs|USA | B7: NonPhysicalInputs, USA | C7: 0.3 | D7: 0.5 | E7: 1.4 | F7: 3.4 | G7: 6.8 | Q7: $B | R7: AI-slice cash = Σ(cash × %EV-AI) from Companies × 0.8 scale-back for 2026.0; history scaled 5/8/20/50%. Used only in E = M + D − c. ESTIMATE.
A8: c|NonPhysicalInputs|CHN | B8: NonPhysicalInputs, China | C8: 0 | D8: 0.1 | E8: 0.2 | F8: 0.4 | G8: 0.8 | Q8: $B | R8: AI-slice cash = Σ(cash × %EV-AI) from Companies × 0.8 scale-back for 2026.0; history scaled 5/8/20/50%. Used only in E = M + D − c. ESTIMATE.
A9: c|NonPhysicalInputs|ROW | B9: NonPhysicalInputs, RoW | C9: 0 | D9: 0 | E9: 0.1 | F9: 0.2 | G9: 0.4 | Q9: $B | R9: AI-slice cash = Σ(cash × %EV-AI) from Companies × 0.8 scale-back for 2026.0; history scaled 5/8/20/50%. Used only in E = M + D − c. ESTIMATE.
A10: c|AICompanies|USA | B10: AICompanies, USA | C10: 7.7 | D10: 12.3 | E10: 30.6 | F10: 76.6 | G10: 153.2 | Q10: $B | R10: AI-slice cash = Σ(cash × %EV-AI) from Companies × 0.8 scale-back for 2026.0; history scaled 5/8/20/50%. Used only in E = M + D − c. ESTIMATE.
A11: c|AICompanies|CHN | B11: AICompanies, China | C11: 0.6 | D11: 1 | E11: 2.6 | F11: 6.4 | G11: 12.8 | Q11: $B | R11: AI-slice cash = Σ(cash × %EV-AI) from Companies × 0.8 scale-back for 2026.0; history scaled 5/8/20/50%. Used only in E = M + D − c. ESTIMATE.
A12: c|AICompanies|ROW | B12: AICompanies, RoW | C12: 0.3 | D12: 0.5 | E12: 1.2 | F12: 3 | G12: 6 | Q12: $B | R12: AI-slice cash = Σ(cash × %EV-AI) from Companies × 0.8 scale-back for 2026.0; history scaled 5/8/20/50%. Used only in E = M + D − c. ESTIMATE.
A13: c|AIDeployers|USA | B13: AIDeployers, USA | C13: 1.1 | D13: 1.7 | E13: 4.4 | F13: 10.9 | G13: 21.8 | Q13: $B | R13: AI-slice cash = Σ(cash × %EV-AI) from Companies × 0.8 scale-back for 2026.0; history scaled 5/8/20/50%. Used only in E = M + D − c. ESTIMATE.
A14: c|AIDeployers|CHN | B14: AIDeployers, China | C14: 0.8 | D14: 1.3 | E14: 3.3 | F14: 8.3 | G14: 16.6 | Q14: $B | R14: AI-slice cash = Σ(cash × %EV-AI) from Companies × 0.8 scale-back for 2026.0; history scaled 5/8/20/50%. Used only in E = M + D − c. ESTIMATE.
A15: c|AIDeployers|ROW | B15: AIDeployers, RoW | C15: 0.4 | D15: 0.7 | E15: 1.7 | F15: 4.2 | G15: 8.3 | Q15: $B | R15: AI-slice cash = Σ(cash × %EV-AI) from Companies × 0.8 scale-back for 2026.0; history scaled 5/8/20/50%. Used only in E = M + D − c. ESTIMATE.

Sheet Parameters
A1: Parameters & assumptions. VALUE = what the dashboard uses. Rows with Bullish/Normal/Bearish entries vary by scenario — the dashboard's preset dropdown overwrites those fields from these columns (Value column stays your hand-set default). θ values derived from Companies sheet.
A3: Key | B3: Value | C3: Bullish (high growth) | D3: Normal (expected) | E3: Bearish (low/crash) | F3: Units | G3: Description | H3: Source / Assumption
A4: r_f | B4: 4.3 | F4: %/yr | G4: Risk-free interest rate r_t (10Y UST) | H4: FRED GS10: 2025 avg 4.29%, Jul-2026 4.60%.
A5: mu | B5: 5 | F5: pp | G5: Spread over r_f that AI companies pay (μ); r_μ = r_f + μ | H5: Model spec ~5pp. Your pause econ model used 8% all-in. SemiAnalysis: backstopped neocloud debt ~5.9%, unsecured ~10%.
A6: g_y0|USA | B6: 1.5 | F6: %/yr | G6: Baseline non-AI GDP growth, USA | H6: Model spec default 1.5%. IMF long-run US real 1.8%.
A7: g_y0|CHN | B7: 4 | F7: %/yr | G7: Baseline non-AI GDP growth, China | H7: IMF: 4.4% (2026) → 3.3% (2031).
A8: g_y0|ROW | B8: 2.8 | F8: %/yr | G8: Baseline non-AI GDP growth, RoW | H8: IMF-implied. ESTIMATE.
A9: psi | B9: 50 | F9: % | G9: ψ: share of compute going to training+R&D normally | H9: Model spec ~50%. Epoch: 45-50% (2024) → ~30-35% (mid-26).
A10: h | B10: 0 | F10: 0-1 | G10: 'Policy priced in already' | H10: Default 0 (surprise).
A11: theta|PhysicalCompute | B11: 65 | F11: % | G11: θ: share of EV from post-2026 AI capability gains | H11: DERIVED from Companies sheet: Σ(cap × %EV>2026-AI)/Σ(cap × %EV-AI). Edit company rows to change.
A12: theta|NonPhysicalInputs | B12: 70 | F12: % | G12: θ for NonPhysicalInputs | H12: Derived from Companies sheet.
A13: theta|AICompanies | B13: 85 | F13: % | G13: θ for AICompanies | H13: Derived from Companies sheet (labs ≈ all future-capability value).
A14: theta|AIDeployers | B14: 58 | F14: % | G14: θ for AIDeployers | H14: Derived from Companies sheet.
A15: theta|NonAI | B15: 0 | F15: % | G15: θ for NonAI | H15: By construction 0.
... A17: a2 | B17: 2 | F17: /yr | G17: a₂: distillation speed | H17: Calibrated: steady-state gap g_z/a2 = 7.5 pts ≈ 6-7 months (Epoch's observed lag).
A18: g_z | B18: 15 | C18: 18 | D18: 15 | E18: 10 | F18: ECI pts/yr | G18: BAU frontier capability growth after 2026 | H18: Epoch: ~15.5 pts/yr since Apr-2024.
A19: g_z_2026 | B19: 15.5 | F19: ECI pts/yr | G19: dZ/dt at 2026.0 (Q-model calibration) | H19: Model spec.
A20: Z_2026|USA | B20: 155 | F20: ECI pts | G20: Z calibration, USA 2026.0 | H20: Model spec.
A21: Z_2026|CHN | B21: 148 | F21: ECI pts | G21: Z calibration, China 2026.0 | H21: Model spec.
A22: m | B22: 1.2 | F22: × | G22: Investment demand multiplier | H22: CBO range 0.5-2.5; MPT ≈1.2. ASSUMPTION.
A23: MPC | B23: 0.032 | F23: $/$ wealth/yr | G23: MPC out of stock wealth | H23: Chodorow-Reich et al. (AER 2021): 3.2c/$/yr.
A24: H|USA | B24: 60 | F24: % | G24: US household share of US market | H24: Fed Z.1: 60.5% (2025Q4).
A25: H|CHN | B25: 30 | F25: % | G25: China household share | H25: ESTIMATE.
A26: H|ROW | B26: 40 | F26: % | G26: RoW household share | H26: ESTIMATE.
A27: wealth_spread_years | B27: 1.5 | F27: yrs | G27: Wealth-effect spread | H27: Model spec.
A28: d|USA | B28: 0.5 | F28: 0-1 | G28: d_j: world AI capex net-additive to USA GDP | H28: ASSUMPTION: ~60% located in US less import leakage.
A29: d|CHN | B29: 0.2 | F29: 0-1 | G29: d_j China | H29: ASSUMPTION.
A30: d|ROW | B30: 0.3 | F30: 0-1 | G30: d_j RoW | H30: ASSUMPTION.
... A38: phi|AIDeployers | B38: 0 | F38: %/yr | G38: φ | H38: Default 0.
A39: g_nonai_W | B39: 5 | C39: 8 | D39: 5 | E39: 0 | F39: %/yr | G39: NonAI market growth post-2026 | H39: ESTIMATE; Presets override.
A40: g_M|PhysicalCompute|2026_29 | B40: 25 | C40: 35 | D40: 25 | E40: 0 | F40: %/yr | G40: Market cap growth, PhysicalCompute, 2026-2029 | H40: BAU appreciation of AI-attributed value. Your pause model used 20%/yr flat for all AI. Presets override.
A41: g_M|PhysicalCompute|2029_32 | B41: 12 | C41: 20 | D41: 12 | E41: 3 | F41: %/yr | G41: Market cap growth, PhysicalCompute, 2029-2032 | H41: Decays as buildout matures. Presets override.
A42: g_M|PhysicalCompute|2032plus | B42: 6 | C42: 12 | D42: 6 | E42: 3 | F42: %/yr | G42: Market cap growth, PhysicalCompute, 2032+ | H42: Presets override.
A43: g_M|NonPhysicalInputs|2026_29 | B43: 22 | C43: 35 | D43: 22 | E43: 5 | F43: %/yr | G43: Market cap growth, NonPhysicalInputs, 2026-2029 | H43: Data/eval/talent scales with training demand. Presets override.
A44: g_M|NonPhysicalInputs|2029_32 | B44: 12 | C44: 22 | D44: 12 | E44: 3 | F44: %/yr | G44: Market cap growth, NonPhysicalInputs, 2029-2032 | H44: Presets override.
A45: g_M|NonPhysicalInputs|2032plus | B45: 8 | C45: 12 | D45: 8 | E45: 3 | F45: %/yr | G45: Market cap growth, NonPhysicalInputs, 2032+ | H45: Presets override.
A46: g_M|AICompanies|2026_29 | B46: 50 | C46: 100 | D46: 50 | E46: 5 | F46: %/yr | G46: Market cap growth, AICompanies (labs), 2026-2029 | H46: Labs re-rate fastest (Anthropic 20x fwd ARR; ARR growing >100%/yr). Presets override.
A47: g_M|AICompanies|2029_32 | B47: 25 | C47: 30 | D47: 25 | E47: 5 | F47: %/yr | G47: Market cap growth, AICompanies, 2029-2032 | H47: Presets override.
A48: g_M|AICompanies|2032plus | B48: 8 | C48: 15 | D48: 8 | E48: 5 | F48: %/yr | G48: Market cap growth, AICompanies, 2032+ | H48: Presets override.
A49: g_M|AIDeployers|2026_29 | B49: 18 | C49: 30 | D49: 18 | E49: 0 | F49: %/yr | G49: Market cap growth, AIDeployers, 2026-2029 | H49: Adoption premium spreads through the broader market. Presets override.
...

Sheet Policies
A1: Preset policies π = {s, p, B, q, t_s, t_e, ω}. Rows sharing a name with different [part n] tags are added together as one stacked scenario. Add rows for more dropdown options.
A3: Name | B3: s (GPU shutoff 0-1) | C3: p (training pause 0-1) | D3: B (buildout pause 0-1) | E3: q (tax, unused) | F3: t_s | G3: t_e | H3: omega
A4: Scenario A — 1-yr worldwide training pause (2029): all training compute shifted to inference | B4: 0 | C4: 1 | D4: 0 | E4: 0 | F4: 2029 | G4: 2030 | H4: USA,CHN,ROW
A5: Scenario B — 1-yr worldwide compute shutoff (2029): all compute off | B5: 1 | C5: 0 | D5: 0 | E5: 0 | F5: 2029 | G5: 2030 | H5: USA,CHN,ROW
A6: Scenario C — 1-yr worldwide AI compute buildout pause (2029): chips & datacenter production paused | B6: 0 | C6: 0 | D6: 1 | E6: 0 | F6: 2029 | G6: 2030 | H6: USA,CHN,ROW
A7: Scenario D — 1-yr unilateral US training pause (2029): US-only, training shifted to inference | B7: 0 | C7: 1 | D7: 0 | E7: 0 | F7: 2029 | G7: 2030 | H7: USA
A8: Scenario E — 6-mo worldwide shutoff, then 2-yr training pause (2029-31) [part 1] | B8: 1 | C8: 0 | D8: 0 | E8: 0 | F8: 2029 | G8: 2029.5 | H8: USA,CHN,ROW
A9: Scenario E — 6-mo worldwide shutoff, then 2-yr training pause (2029-31) [part 2] | B9: 0 | C9: 1 | D9: 0 | E9: 0 | F9: 2029.5 | G9: 2031.5 | H9: USA,CHN,ROW
A10: Scenario F — training reduced 75% worldwide for 3 yrs (2029-32) | B10: 0 | C10: 0.75 | D10: 0 | E10: 0 | F10: 2029 | G10: 2032 | H10: USA,CHN,ROW
